<?xml version="1.0" ?>

<robot name="$(arg roboname)" xmlns:xacro="http://www.ros.org/wiki/xacro">

  <xacro:property name="PI" value="3.141592653589793"/>

  <!-- base -->
  <xacro:property name="base_length" value="2.695"/>
  <xacro:property name="base_width" value="0.68"/>
  <xacro:property name="base_height" value="1.370"/>
  <xacro:property name="base_collision_height" value="0.875"/>
  <xacro:property name="base_mass" value="956"/>

  <!-- rear tyre -->
  <xacro:property name="rear_tyre_x" value="0.945"/>
  <xacro:property name="rear_tyre_y" value="0.642"/>
  <xacro:property name="rear_tyre_r" value="0.3"/>
  <xacro:property name="rear_tyre_length" value="0.165"/>
  <xacro:property name="rear_tyre_mass" value="20"/>

  <!-- front tyre -->
  <xacro:property name="front_tyre_x" value="0.923"/>
  <xacro:property name="front_tyre_y" value="0.642"/>
  <xacro:property name="front_tyre_r" value="0.3"/>
  <xacro:property name="front_tyre_length" value="0.165"/>
  <xacro:property name="front_tyre_mass" value="20"/>

  <!-- steering -->
  <xacro:property name="str_angle" value="0.6"/>    
  <xacro:property name="str_length" value="0.01"/>
  <xacro:property name="str_radius" value="0.1"/>
  <xacro:property name="str_mass" value="5"/>

  <!--Car Body-->
  <link name="base_link">
    <collision>
      <origin xyz="0 0 ${base_collision_height}" rpy="0 0 0"/>  
      <geometry>
        <box size="${base_length} ${base_width} ${base_height}"/>
      </geometry>
    </collision>

    <visual>
      <origin xyz="0 0 ${base_collision_height}" rpy="0 0 0"/>  
      <geometry>
        <box size="${base_length} ${base_width} ${base_height}"/>
        <!-- <mesh filename="package://carmodel/meshes/vehicle_body.dae"/> -->
      </geometry>
    </visual>
  </link>

  <joint name="inertial_joint" type="fixed">
    <parent link="base_link"/>
    <child link="main_mass"/>
    <origin xyz="0 0 0" rpy="0 0 0"/>
  </joint>  

  <link name="main_mass" type="fixed">
    <xacro:Box_inertial_matrix m="${base_mass}" l="${base_length}" w="${base_width}" h="${base_height}" />
  </link>


  <!--Rear Right Wheel-->
  <joint name="rear_right_wheel_joint" type="continuous">
    <parent link="base_link"/>
    <child link="rear_right_wheel_link"/>
    <origin xyz="${-rear_tyre_x} ${-rear_tyre_y} ${rear_tyre_r}" rpy="0 0 0"/>
    <axis xyz="0 1 0"/>
    <dynamics damping="0.1"/>
    <limit effort="100000" velocity="10000" />
    <joint_properties damping="0.0" friction="0.0" />
  </joint>

  <link name="rear_right_wheel_link">
    <collision>
      <origin xyz="0 0 0" rpy="${PI/2} 0 0"/>
      <geometry>
        <cylinder length="${rear_tyre_length}" radius="${rear_tyre_r}"/>
      </geometry>
    </collision>

    <visual>
      <origin xyz="0 0 0" rpy="${PI/2} 0 0"/>
      <geometry>
        <cylinder length="${rear_tyre_length}" radius="${rear_tyre_r}"/>
      </geometry>
    </visual>

    <xacro:cylinder_inertial_matrix m="${rear_tyre_mass}" r="${rear_tyre_r}" h="${rear_tyre_length}" />
  </link>

  <!--Rear Left Wheel-->
  <joint name="rear_left_wheel_joint" type="continuous">
    <parent link="base_link"/>
    <child link="rear_left_wheel_link"/>
    <origin xyz="${-rear_tyre_x} ${rear_tyre_y} ${rear_tyre_r}" rpy="0 0 0"/>
    <axis xyz="0 1 0"/>
    <dynamics damping="0.1"/>
    <limit effort="100000" velocity="10000" />
    <joint_properties damping="0.0" friction="0.0" />
  </joint>

  <link name="rear_left_wheel_link">
    <collision>
      <origin xyz="0 0 0" rpy="${PI/2} 0 0"/>
      <geometry>
        <cylinder length="${rear_tyre_length}" radius="${rear_tyre_r}"/>
      </geometry>
    </collision>

    <visual>
      <origin xyz="0 0 0" rpy="${PI/2} 0 0"/>
      <geometry>
        <cylinder length="${rear_tyre_length}" radius="${rear_tyre_r}"/>
      </geometry>
    </visual>
    <xacro:cylinder_inertial_matrix m="${rear_tyre_mass}" r="${rear_tyre_r}" h="${rear_tyre_length}" />
  </link> 

  <!--Front Right Steering-->
  <joint name="front_right_steering_joint" type="revolute">
    <parent link="base_link"/>
    <child link="front_right_steering_link"/>
    <origin xyz="${front_tyre_x} ${-front_tyre_y} ${front_tyre_r}" rpy="0 0 0"/>
    <axis xyz="0 0 1"/>
    <limit lower="${-str_angle}" upper="${str_angle}" effort="1000000.0" velocity="10000.0"/>
    <dynamics damping="10.0" friction="0.0"/>
  </joint>

  <link name="front_right_steering_link">
    <visual>
      <origin xyz="0 0 0" rpy="${PI/2} 0 0"/>
      <geometry>
        <cylinder length="${str_length}" radius="${str_radius}"/>
      </geometry>
    </visual>

    <xacro:cylinder_inertial_matrix m="${str_mass}" r="${str_radius}" h="${str_length}" />
  </link>


  <!--Front Right Wheel-->
  <joint name="front_right_wheel_joint" type="continuous">
    <parent link="front_right_steering_link"/>
    <child link="front_right_wheel_link"/>
    <origin xyz="0 0 0" rpy="0 0 0"/>
    <axis xyz="0 1 0"/>
    <dynamics damping="0.1"/>
    <limit effort="1000000" velocity="10000" />
    <joint_properties damping="0.0" friction="0.0" />
  </joint>

  <link name="front_right_wheel_link">
    <collision>
      <origin xyz="0 0 0" rpy="${PI/2} 0 0"/>
      <geometry>
        <cylinder length="${front_tyre_length}" radius="${front_tyre_r}"/>
      </geometry>
    </collision>

    <visual>
      <origin xyz="0 0 0" rpy="${PI/2} 0 0"/>
      <geometry>
        <cylinder length="${front_tyre_length}" radius="${front_tyre_r}"/>
      </geometry>  
    </visual>

    <xacro:cylinder_inertial_matrix m="${front_tyre_mass}" r="${front_tyre_r}" h="${front_tyre_length}" />
  </link>

  <!--Front Left Steering-->
  <joint name="front_left_steering_joint" type="revolute">
    <parent link="base_link"/>
    <child link="front_left_steering_link"/>
    <origin xyz="${front_tyre_x} ${front_tyre_y} ${front_tyre_r}" rpy="0 0 0"/>
    <axis xyz="0 0 1"/>
    <limit lower="${-str_angle}" upper="${str_angle}" effort="1000000.0" velocity="10000.0"/>
    <dynamics damping="10.0" friction="0.0"/>
  </joint>

  <link name="front_left_steering_link">

    <visual>
      <origin xyz="0 0 0" rpy="${PI/2} 0 0"/>
      <geometry>
        <cylinder length="${str_length}" radius="${str_radius}"/>
      </geometry>
    </visual>

    <xacro:cylinder_inertial_matrix m="${str_mass}" r="${str_radius}" h="${str_length}" />
  </link>


  <!--Front Left Wheel-->
  <joint name="front_left_wheel_joint" type="continuous">
    <parent link="front_left_steering_link"/>
    <child link="front_left_wheel_link"/>
    <origin xyz="0 0 0" rpy="0 0 0"/>
    <axis xyz="0 1 0"/>
    <dynamics damping="0.1"/>
    <limit effort="1000000" velocity="10000" />
    <joint_properties damping="0.0" friction="0.0" />
  </joint>

  <link name="front_left_wheel_link">
    <collision>
      <origin xyz="0 0 0" rpy="${PI/2} 0 0"/>
      <geometry>
        <cylinder length="${front_tyre_length}" radius="${front_tyre_r}"/>
      </geometry>
    </collision>

    <visual>
      <origin xyz="0 0 0" rpy="${PI/2} 0 0"/>
      <geometry>
        <cylinder length="${front_tyre_length}" radius="${front_tyre_r}"/>
      </geometry>  
    </visual>

    <xacro:cylinder_inertial_matrix m="${front_tyre_mass}" r="${front_tyre_r}" h="${front_tyre_length}" />
  </link>  


</robot>
